Workbook
Name Slicer_Cancer_History1: #N/A
Name Slicer_City_Tier: #N/A

Sheet Cleaned - Customer Names 
A1: Customer ID | B1: Title | C1: First Name | D1: Last Name
A2: Id1 | B2: Ms | C2: Kelly | D2: Hawks
A3: Id2 | B3: Mr | C3: Matthew D | D3: Lehner
A4: Id3 | B4: Mr | C4: Phil | D4: Lu
A5: Id4 | B5: Ms | C5: Kelsey | D5: Osborne
A6: Id5 | B6: Ms | C6: Kristyn | D6: Kadala
A7: Id6 | B7: Mr | C7: Russell B. | D7: Baker
A8: Id7 | B8: Mr | C8: Scott | D8: Macpherson
A9: Id8 | B9: Mr | C9: Stephen | D9: Hallman
A10: Id9 | B10: Mr | C10: Patrick R. | D10: Moran
A11: Id10 | B11: Ms | C11: Brooke N. | D11: Benner
A12: Id11 | B12: Ms | C12: Paola Andrea | D12: Fierro Vargas
... A2336: Id2335 | B2336: Mr | C2336: Aaron K | D2336: German

Sheet Cleaned - Medical Examinations
A1: Customer ID | B1: BMI | C1: HBA1C | D1: Heart Issues | E1: Any Transplants | F1: Cancer history | G1: NumberOfMajorSurgeries | H1: Smoker | I1: Weight Status | J1: Mode Of Smoker
A2: Id1 | B2: 47.41 | C2: 7.47 | D2: No | E2: No | F2: No | G2: 0 | H2: Yes | I2: =IF(B2<18.5,"Underweight", IF(B2<=24.9,"Normal Weight", IF(B2<=29.9,"Overweight", "Obesity"))) -> Obesity | J2: {=INDEX(H2:H2336,MODE(MATCH(H2:H2336,H2:H2336,0)))} -> No
A3: Id2 | B3: 30.36 | C3: 5.77 | D3: No | E3: No | F3: No | G3: 0 | H3: Yes | I3: =IF(B3<18.5,"Underweight", IF(B3<=24.9,"Normal Weight", IF(B3<=29.9,"Overweight", "Obesity"))) -> Obesity
A4: Id3 | B4: 34.485 | C4: 11.87 | D4: Yes | E4: No | F4: No | G4: 2 | H4: Yes | I4: =IF(B4<18.5,"Underweight", IF(B4<=24.9,"Normal Weight", IF(B4<=29.9,"Overweight", "Obesity"))) -> Obesity
A5: Id4 | B5: 38.095 | C5: 6.05 | D5: No | E5: No | F5: No | G5: 0 | H5: Yes | I5: =IF(B5<18.5,"Underweight", IF(B5<=24.9,"Normal Weight", IF(B5<=29.9,"Overweight", "Obesity"))) -> Obesity
A6: Id5 | B6: 35.53 | C6: 5.45 | D6: No | E6: No | F6: No | G6: 0 | H6: Yes | I6: =IF(B6<18.5,"Underweight", IF(B6<=24.9,"Normal Weight", IF(B6<=29.9,"Overweight", "Obesity"))) -> Obesity
A7: Id6 | B7: 32.8 | C7: 6.59 | D7: No | E7: No | F7: No | G7: 0 | H7: Yes | I7: =IF(B7<18.5,"Underweight", IF(B7<=24.9,"Normal Weight", IF(B7<=29.9,"Overweight", "Obesity"))) -> Obesity
A8: Id7 | B8: 36.4 | C8: 6.07 | D8: No | E8: No | F8: No | G8: 0 | H8: Yes | I8: =IF(B8<18.5,"Underweight", IF(B8<=24.9,"Normal Weight", IF(B8<=29.9,"Overweight", "Obesity"))) -> Obesity
A9: Id8 | B9: 36.96 | C9: 7.93 | D9: No | E9: No | F9: No | G9: 3 | H9: Yes | I9: =IF(B9<18.5,"Underweight", IF(B9<=24.9,"Normal Weight", IF(B9<=29.9,"Overweight", "Obesity"))) -> Obesity
A10: Id9 | B10: 41.14 | C10: 9.58 | D10: Yes | E10: No | F10: Yes | G10: 1 | H10: Yes | I10: =IF(B10<18.5,"Underweight", IF(B10<=24.9,"Normal Weight", IF(B10<=29.9,"Overweight", "Obesity"))) -> Obesity
A11: Id10 | B11: 38.06 | C11: 10.79 | D11: No | E11: No | F11: No | G11: 0 | H11: Yes | I11: =IF(B11<18.5,"Underweight", IF(B11<=24.9,"Normal Weight", IF(B11<=29.9,"Overweight", "Obesity"))) -> Obesity
A12: Id11 | B12: 37.7 | C12: 5.96 | D12: Yes | E12: No | F12: No | G12: 2 | H12: Yes | I12: =IF(B12<18.5,"Underweight", IF(B12<=24.9,"Normal Weight", IF(B12<=29.9,"Overweight", "Obesity"))) -> Obesity
A13: Id12 | B13: 42.13 | C13: 11.9 | D13: No | E13: No | F13: No | G13: 0 | H13: Yes | I13: =IF(B13<18.5,"Underweight", IF(B13<=24.9,"Normal Weight", IF(B13<=29.9,"Overweight", "Obesity"))) -> Obesity
A14: Id13 | B14: 40.92 | C14: 8.41 | D14: No | E14: No | F14: No | G14: 0 | H14: Yes | I14: =IF(B14<18.5,"Underweight", IF(B14<=24.9,"Normal Weight", IF(B14<=29.9,"Overweight", "Obesity"))) -> Obesity
... A2336: Id2335 | B2336: 17.58 | C2336: 4.51 | D2336: No | E2336: No | F2336: No | G2336: 1 | H2336: No | I2336: =IF(B2336<18.5,"Underweight", IF(B2336<=24.9,"Normal Weight", IF(B2336<=29.9,"Overweight", "Obesity"))) -> Underweight

Sheet Cleaned - Hospitalisation Detai
A1: Customer ID | B1: Year | C1: Month | D1: Date | E1: Children | F1: Charges | G1: Hospital Tier | H1: City Tier | I1: State ID | J1: Date of Birth | K1: Age | L1: Year Average | M1: Mode of Month | N1: Mode of Hospital Tier | O1: Mode of City Tier
A2: Id2335 | B2: 1992 | C2: Jul | D2: 9 | E2: 0 | F2: 563.84 | G2: tier - 2 | H2: tier - 3 | I2: R1013 | J2: =DATE(B2,MONTH(DATEVALUE(C2&" 1")),D2) -> 33794 | K2: =DATEDIF(J2,DATE(2023,6,8),"Y") -> 30 | L2: =ROUND(AVERAGE(B2:B2344),0) -> 1983 | M2: {=INDEX(C2:C2344,MODE(MATCH(C2:C2344,C2:C2344,0)))} -> Sep | N2: {=INDEX(G2:G2344,MODE(MATCH(G2:G2344,G2:G2344,0)))} -> tier - 2 | O2: {=INDEX(H2:H2344,MODE(MATCH(H2:H2344,H2:H2344,0)))} -> tier - 2
A3: Id2334 | B3: 1992 | C3: Nov | D3: 30 | E3: 0 | F3: 570.62 | G3: tier - 2 | H3: tier - 1 | I3: R1013 | J3: =DATE(B3,MONTH(DATEVALUE(C3&" 1")),D3) -> 33938 | K3: =DATEDIF(J3,DATE(2023,6,8),"Y") -> 30
A4: Id2333 | B4: 1993 | C4: Jun | D4: 30 | E4: 0 | F4: 600 | G4: tier - 2 | H4: tier - 1 | I4: R1013 | J4: =DATE(B4,MONTH(DATEVALUE(C4&" 1")),D4) -> 34150 | K4: =DATEDIF(J4,DATE(2023,6,8),"Y") -> 29
A5: Id2332 | B5: 1992 | C5: Sep | D5: 13 | E5: 0 | F5: 604.54 | G5: tier - 3 | H5: tier - 3 | I5: R1013 | J5: =DATE(B5,MONTH(DATEVALUE(C5&" 1")),D5) -> 33860 | K5: =DATEDIF(J5,DATE(2023,6,8),"Y") -> 30
A6: Id2331 | B6: 1998 | C6: Jul | D6: 27 | E6: 0 | F6: 637.26 | G6: tier - 3 | H6: tier - 3 | I6: R1013 | J6: =DATE(B6,MONTH(DATEVALUE(C6&" 1")),D6) -> 36003 | K6: =DATEDIF(J6,DATE(2023,6,8),"Y") -> 24
A7: Id2330 | B7: 2001 | C7: Nov | D7: 20 | E7: 0 | F7: 646.14 | G7: tier - 3 | H7: tier - 3 | I7: R1012 | J7: =DATE(B7,MONTH(DATEVALUE(C7&" 1")),D7) -> 37215 | K7: =DATEDIF(J7,DATE(2023,6,8),"Y") -> 21
A8: Id2329 | B8: 1993 | C8: Jun | D8: 1 | E8: 0 | F8: 650 | G8: tier - 3 | H8: tier - 3 | I8: R1013 | J8: =DATE(B8,MONTH(DATEVALUE(C8&" 1")),D8) -> 34121 | K8: =DATEDIF(J8,DATE(2023,6,8),"Y") -> 30
A9: Id2328 | B9: 1995 | C9: Jul | D9: 4 | E9: 0 | F9: 650 | G9: tier - 3 | H9: tier - 3 | I9: R1013 | J9: =DATE(B9,MONTH(DATEVALUE(C9&" 1")),D9) -> 34884 | K9: =DATEDIF(J9,DATE(2023,6,8),"Y") -> 27
A10: Id2327 | B10: 2002 | C10: Nov | D10: 29 | E10: 0 | F10: 668 | G10: tier - 3 | H10: tier - 2 | I10: R1012 | J10: =DATE(B10,MONTH(DATEVALUE(C10&" 1")),D10) -> 37589 | K10: =DATEDIF(J10,DATE(2023,6,8),"Y") -> 20
A11: Id2326 | B11: 1997 | C11: Nov | D11: 9 | E11: 0 | F11: 670 | G11: tier - 3 | H11: tier - 3 | I11: R1013 | J11: =DATE(B11,MONTH(DATEVALUE(C11&" 1")),D11) -> 35743 | K11: =DATEDIF(J11,DATE(2023,6,8),"Y") -> 25
A12: Id2325 | B12: 2001 | C12: Sep | D12: 12 | E12: 0 | F12: 687.54 | G12: tier - 3 | H12: tier - 2 | I12: R1013 | J12: =DATE(B12,MONTH(DATEVALUE(C12&" 1")),D12) -> 37146 | K12: =DATEDIF(J12,DATE(2023,6,8),"Y") -> 21
A13: Id2324 | B13: 1999 | C13: Dec | D13: 26 | E13: 0 | F13: 700 | G13: tier - 2 | H13: tier - 3 | I13: R1013 | J13: =DATE(B13,MONTH(DATEVALUE(C13&" 1")),D13) -> 36520 | K13: =DATEDIF(J13,DATE(2023,6,8),"Y") -> 23
A14: Id2323 | B14: 1999 | C14: Dec | D14: 14 | E14: 0 | F14: 722.99 | G14: tier - 3 | H14: tier - 1 | I14: R1013 | J14: =DATE(B14,MONTH(DATEVALUE(C14&" 1")),D14) -> 36508 | K14: =DATEDIF(J14,DATE(2023,6,8),"Y") -> 23
... A46: Id2291 | B46: 2002 | C46: Aug | D46: 11 | E46: 0 | F46: 1137 | G46: tier - 3 | H46: tier - 1 | I46: R1013 | J46: =DATE(B46,MONTH(DATEVALUE(C46&" 1")),D46) -> 37479 | K46: =DATEDIF(J46,DATE(2023,6,8),"Y") -> 20
A47: Unknown | B47: 2004 | C47: Nov | D47: 6 | E47: 0 | F47: 1137.01 | G47: tier - 3 | H47: tier - 1 | I47: R1013 | J47: =DATE(B47,MONTH(DATEVALUE(C47&" 1")),D47) -> 38297 | K47: =DATEDIF(J47,DATE(2023,6,8),"Y") -> 18 | L47: Id2294 | M47: Id2294
A48: Id2290 | B48: 2004 | C48: Oct | D48: 15 | E48: 0 | F48: 1137.01 | G48: tier - 3 | H48: tier - 1 | I48: R1013 | J48: =DATE(B48,MONTH(DATEVALUE(C48&" 1")),D48) -> 38275 | K48: =DATEDIF(J48,DATE(2023,6,8),"Y") -> 18
A49: Id2289 | B49: 2004 | C49: Nov | D49: 27 | E49: 0 | F49: 1137.47 | G49: tier - 3 | H49: tier - 2 | I49: R1013 | J49: =DATE(B49,MONTH(DATEVALUE(C49&" 1")),D49) -> 38318 | K49: =DATEDIF(J49,DATE(2023,6,8),"Y") -> 18
A50: Id2288 | B50: 2001 | C50: Oct | D50: 25 | E50: 0 | F50: 1141 | G50: tier - 3 | H50: tier - 1 | I50: R1013 | J50: =DATE(B50,MONTH(DATEVALUE(C50&" 1")),D50) -> 37189 | K50: =DATEDIF(J50,DATE(2023,6,8),"Y") -> 21
A51: Id2287 | B51: 2004 | C51: Sep | D51: 12 | E51: 0 | F51: 1141.45 | G51: tier - 3 | H51: tier - 3 | I51: R1013 | J51: =DATE(B51,MONTH(DATEVALUE(C51&" 1")),D51) -> 38242 | K51: =DATEDIF(J51,DATE(2023,6,8),"Y") -> 18
A52: Id2286 | B52: 2002 | C52: Oct | D52: 1 | E52: 0 | F52: 1142 | G52: tier - 3 | H52: tier - 2 | I52: R1011 | J52: =DATE(B52,MONTH(DATEVALUE(C52&" 1")),D52) -> 37530 | K52: =DATEDIF(J52,DATE(2023,6,8),"Y") -> 20
A53: Id2285 | B53: 2004 | C53: Jun | D53: 10 | E53: 0 | F53: 1146.8 | G53: tier - 2 | H53: tier - 2 | I53: R1013 | J53: =DATE(B53,MONTH(DATEVALUE(C53&" 1")),D53) -> 38148 | K53: =DATEDIF(J53,DATE(2023,6,8),"Y") -> 18
A54: Id2284 | B54: 2003 | C54: Jun | D54: 12 | E54: 0 | F54: 1149 | G54: tier - 2 | H54: tier - 1 | I54: R1012 | J54: =DATE(B54,MONTH(DATEVALUE(C54&" 1")),D54) -> 37784 | K54: =DATEDIF(J54,DATE(2023,6,8),"Y") -> 19
A55: Id2283 | B55: 2004 | C55: Jul | D55: 18 | E55: 0 | F55: 1149.4 | G55: tier - 2 | H55: tier - 2 | I55: R1013 | J55: =DATE(B55,MONTH(DATEVALUE(C55&" 1")),D55) -> 38186 | K55: =DATEDIF(J55,DATE(2023,6,8),"Y") -> 18
A56: Id2282 | B56: 1994 | C56: Jul | D56: 26 | E56: 0 | F56: 1158.32 | G56: tier - 2 | H56: tier - 1 | I56: R1013 | J56: =DATE(B56,MONTH(DATEVALUE(C56&" 1")),D56) -> 34541 | K56: =DATEDIF(J56,DATE(2023,6,8),"Y") -> 28
A57: Id2281 | B57: 2004 | C57: Nov | D57: 11 | E57: 0 | F57: 1163.46 | G57: tier - 2 | H57: tier - 3 | I57: R1013 | J57: =DATE(B57,MONTH(DATEVALUE(C57&" 1")),D57) -> 38302 | K57: =DATEDIF(J57,DATE(2023,6,8),"Y") -> 18
A58: Id2280 | B58: 2002 | C58: Jun | D58: 11 | E58: 0 | F58: 1165 | G58: tier - 2 | H58: tier - 3 | I58: R1012 | J58: =DATE(B58,MONTH(DATEVALUE(C58&" 1")),D58) -> 37418 | K58: =DATEDIF(J58,DATE(2023,6,8),"Y") -> 20
A59: Id2279 | B59: 2001 | C59: Nov | D59: 12 | E59: 0 | F59: 1167 | G59: tier - 2 | H59: tier - 1 | I59: R1013 | J59: =DATE(B59,MONTH(DATEVALUE(C59&" 1")),D59) -> 37207 | K59: =DATEDIF(J59,DATE(2023,6,8),"Y") -> 21
... A295: Id2043 | B295: 2004 | C295: Nov | D295: 14 | E295: 0 | F295: 2773.46 | G295: tier - 2 | H295: tier - 1 | I295: R1021 | J295: =DATE(B295,MONTH(DATEVALUE(C295&" 1")),D295) -> 38305 | K295: =DATEDIF(J295,DATE(2023,6,8),"Y") -> 18
A296: Unknown | B296: 1999 | C296: Jun | D296: 9 | E296: 1 | F296: 2775.19 | G296: tier - 2 | H296: tier - 1 | I296: R1012 | J296: =DATE(B296,MONTH(DATEVALUE(C296&" 1")),D296) -> 36320 | K296: =DATEDIF(J296,DATE(2023,6,8),"Y") -> 23 | L296: Id2045 | M296: Id2045
A297: Id2042 | B297: 1999 | C297: Aug | D297: 29 | E297: 1 | F297: 2775.19 | G297: tier - 2 | H297: tier - 1 | I297: R1012 | J297: =DATE(B297,MONTH(DATEVALUE(C297&" 1")),D297) -> 36401 | K297: =DATEDIF(J297,DATE(2023,6,8),"Y") -> 23
A298: Id2041 | B298: 1999 | C298: Dec | D298: 24 | E298: 1 | F298: 2789.06 | G298: tier - 2 | H298: tier - 3 | I298: R1012 | J298: =DATE(B298,MONTH(DATEVALUE(C298&" 1")),D298) -> 36518 | K298: =DATEDIF(J298,DATE(2023,6,8),"Y") -> 23
A299: Id2040 | B299: 2004 | C299: Aug | D299: 4 | E299: 2 | F299: 2801.26 | G299: tier - 2 | H299: tier - 3 | I299: R1013 | J299: =DATE(B299,MONTH(DATEVALUE(C299&" 1")),D299) -> 38203 | K299: =DATEDIF(J299,DATE(2023,6,8),"Y") -> 18
A300: Id2039 | B300: 2003 | C300: Sep | D300: 23 | E300: 2 | F300: 2803.7 | G300: tier - 2 | H300: tier - 1 | I300: R1012 | J300: =DATE(B300,MONTH(DATEVALUE(C300&" 1")),D300) -> 37887 | K300: =DATEDIF(J300,DATE(2023,6,8),"Y") -> 19
A301: Id2038 | B301: 2000 | C301: Oct | D301: 1 | E301: 0 | F301: 2819.51 | G301: tier - 2 | H301: tier - 3 | I301: R1011 | J301: =DATE(B301,MONTH(DATEVALUE(C301&" 1")),D301) -> 36800 | K301: =DATEDIF(J301,DATE(2023,6,8),"Y") -> 22
A302: Id2037 | B302: 1998 | C302: Nov | D302: 15 | E302: 0 | F302: 2842.76 | G302: tier - 2 | H302: tier - 3 | I302: R1012 | J302: =DATE(B302,MONTH(DATEVALUE(C302&" 1")),D302) -> 36114 | K302: =DATEDIF(J302,DATE(2023,6,8),"Y") -> 24
A303: Id2036 | B303: 1998 | C303: Jun | D303: 17 | E303: 0 | F303: 2850.68 | G303: tier - 2 | H303: tier - 3 | I303: R1012 | J303: =DATE(B303,MONTH(DATEVALUE(C303&" 1")),D303) -> 35963 | K303: =DATEDIF(J303,DATE(2023,6,8),"Y") -> 24
A304: Id2035 | B304: 1998 | C304: Sep | D304: 4 | E304: 0 | F304: 2855.44 | G304: tier - 2 | H304: tier - 3 | I304: R1012 | J304: =DATE(B304,MONTH(DATEVALUE(C304&" 1")),D304) -> 36042 | K304: =DATEDIF(J304,DATE(2023,6,8),"Y") -> 24
A305: Id2034 | B305: 1993 | C305: Nov | D305: 1 | E305: 0 | F305: 2866.09 | G305: tier - 3 | H305: tier - 3 | I305: R1011 | J305: =DATE(B305,MONTH(DATEVALUE(C305&" 1")),D305) -> 34274 | K305: =DATEDIF(J305,DATE(2023,6,8),"Y") -> 29
A306: Id2033 | B306: 1993 | C306: Aug | D306: 12 | E306: 0 | F306: 2867.12 | G306: tier - 1 | H306: tier - 3 | I306: R1013 | J306: =DATE(B306,MONTH(DATEVALUE(C306&" 1")),D306) -> 34193 | K306: =DATEDIF(J306,DATE(2023,6,8),"Y") -> 29
...

Sheet Healthcare
A1: Customer ID | B1: First Name | C1: BMI | D1: HBA1C | E1: Heart Issues | F1: Any Transplants | G1: Cancer History | H1: Number of Major Surgeries | I1: Smoker | J1: Weight Status | K1: Diabetes Status | L1: Date of Birth | M1: Charges | N1: Hospital Tier | O1: City Tier | P1: State ID | Q1: Age
A2: Id1 | B2: =_xlfn.XLOOKUP(A2,'Cleaned - Customer Names '!$A$2:$A$2336,'Cleaned - Customer Names '!$C$2:$C$2336,0) -> Kelly | C2: =_xlfn.XLOOKUP($A2,'Cleaned - Medical Examinations'!$A$2:$A$2336,'Cleaned - Medical Examinations'!$B$2:$B$2336,0) -> 47.41 | D2: =_xlfn.XLOOKUP($A2,'Cleaned - Medical Examinations'!$A$2:$A$2336,'Cleaned - Medical Examinations'!$C$2:$C$2336,0) -> 7.47 | E2: =_xlfn.XLOOKUP($A2,'Cleaned - Medical Examinations'!$A$2:$A$2336,'Cleaned - Medical Examinations'!$D$2:$D$2336,0) -> No | F2: =_xlfn.XLOOKUP($A2,'Cleaned - Medical Examinations'!$A$2:$A$2336,'Cleaned - Medical Examinations'!$E$2:$E$2336,0) -> No | G2: =_xlfn.XLOOKUP($A2,'Cleaned - Medical Examinations'!$A$2:$A$2336,'Cleaned - Medical Examinations'!$F$2:$F$2336,0) -> No | H2: =_xlfn.XLOOKUP($A2,'Cleaned - Medical Examinations'!$A$2:$A$2336,'Cleaned - Medical Examinations'!$G$2:$G$2336,0) -> 0 | I2: =_xlfn.XLOOKUP($A2,'Cleaned - Medical Examinations'!$A$2:$A$2336,'Cleaned - Medical Examinations'!$H$2:$H$2336,0) -> Yes | J2: =_xlfn.XLOOKUP($A2,'Cleaned - Medical Examinations'!$A$2:$A$2336,'Cleaned - Medical Examinations'!$I$2:$I$2336,0) -> Obesity | K2: =IF(D2>=6.5,"Diabetic","Non-Diabetic") -> Diabetic | L2: =_xlfn.XLOOKUP($A2,'Cleaned - Hospitalisation Detai'!$A$2:$A$2344,'Cleaned - Hospitalisation Detai'!$J$2:$J$2344,0) -> 25123 | M2: =_xlfn.XLOOKUP($A2,'Cleaned - Hospitalisation Detai'!$A$2:$A$2344,'Cleaned - Hospitalisation Detai'!$F$2:$F$2344,0) -> 63770.43 | N2: =_xlfn.XLOOKUP($A2,'Cleaned - Hospitalisation Detai'!$A$2:$A$2344,'Cleaned - Hospitalisation Detai'!$G$2:$G$2344,0) -> tier - 1 | O2: =_xlfn.XLOOKUP($A2,'Cleaned - Hospitalisation Detai'!$A$2:$A$2344,'Cleaned - Hospitalisation Detai'!$H$2:$H$2344,0) -> tier - 3 | P2: =_xlfn.XLOOKUP($A2,'Cleaned - Hospitalisation Detai'!$A$2:$A$2344,'Cleaned - Hospitalisation Detai'!$I$2:$I$2344,0) -> R1013 | Q2: =_xlfn.XLOOKUP($A2,'Cleaned - Hospitalisation Detai'!$A$2:$A$2344,'Cleaned - Hospitalisation Detai'!$K$2:$K$2344,0) -> 54
A3: Id2 | B3: =_xlfn.XLOOKUP(A3,'Cleaned - Customer Names '!$A$2:$A$2336,'Cleaned - Customer Names '!$C$2:$C$2336,0) -> Matthew D | C3: =_xlfn.XLOOKUP($A3,'Cleaned - Medical Examinations'!$A$2:$A$2336,'Cleaned - Medical Examinations'!$B$2:$B$2336,0) -> 30.36 | D3: =_xlfn.XLOOKUP($A3,'Cleaned - Medical Examinations'!$A$2:$A$2336,'Cleaned - Medical Examinations'!$C$2:$C$2336,0) -> 5.77 | E3: =_xlfn.XLOOKUP($A3,'Cleaned - Medical Examinations'!$A$2:$A$2336,'Cleaned - Medical Examinations'!$D$2:$D$2336,0) -> No | F3: =_xlfn.XLOOKUP($A3,'Cleaned - Medical Examinations'!$A$2:$A$2336,'Cleaned - Medical Examinations'!$E$2:$E$2336,0) -> No | G3: =_xlfn.XLOOKUP($A3,'Cleaned - Medical Examinations'!$A$2:$A$2336,'Cleaned - Medical Examinations'!$F$2:$F$2336,0) -> No | H3: =_xlfn.XLOOKUP($A3,'Cleaned - Medical Examinations'!$A$2:$A$2336,'Cleaned - Medical Examinations'!$G$2:$G$2336,0) -> 0 | I3: =_xlfn.XLOOKUP($A3,'Cleaned - Medical Examinations'!$A$2:$A$2336,'Cleaned - Medical Examinations'!$H$2:$H$2336,0) -> Yes | J3: =_xlfn.XLOOKUP($A3,'Cleaned - Medical Examinations'!$A$2:$A$2336,'Cleaned - Medical Examinations'!$I$2:$I$2336,0) -> Obesity | K3: =IF(D3>=6.5,"Diabetic","Non-Diabetic") -> Non-Diabetic | L3: =_xlfn.XLOOKUP($A3,'Cleaned - Hospitalisation Detai'!$A$2:$A$2344,'Cleaned - Hospitalisation Detai'!$J$2:$J$2344,0) -> 28284 | M3: =_xlfn.XLOOKUP($A3,'Cleaned - Hospitalisation Detai'!$A$2:$A$2344,'Cleaned - Hospitalisation Detai'!$F$2:$F$2344,0) -> 62592.87 | N3: =_xlfn.XLOOKUP($A3,'Cleaned - Hospitalisation Detai'!$A$2:$A$2344,'Cleaned - Hospitalisation Detai'!$G$2:$G$2344,0) -> tier - 2 | O3: =_xlfn.XLOOKUP($A3,'Cleaned - Hospitalisation Detai'!$A$2:$A$2344,'Cleaned - Hospitalisation Detai'!$H$2:$H$2344,0) -> tier - 3 | P3: =_xlfn.XLOOKUP($A3,'Cleaned - Hospitalisation Detai'!$A$2:$A$2344,'Cleaned - Hospitalisation Detai'!$I$2:$I$2344,0) -> R1013 | Q3: =_xlfn.XLOOKUP($A3,'Cleaned - Hospitalisation Detai'!$A$2:$A$2344,'Cleaned - Hospitalisation Detai'!$K$2:$K$2344,0) -> 46
A4: Id3 | B4: =_xlfn.XLOOKUP(A4,'Cleaned - Customer Names '!$A$2:$A$2336,'Cleaned - Customer Names '!$C$2:$C$2336,0) -> Phil | C4: =_xlfn.XLOOKUP($A4,'Cleaned - Medical Examinations'!$A$2:$A$2336,'Cleaned - Medical Examinations'!$B$2:$B$2336,0) -> 34.485 | D4: =_xlfn.XLOOKUP($A4,'Cleaned - Medical Examinations'!$A$2:$A$2336,'Cleaned - Medical Examinations'!$C$2:$C$2336,0) -> 11.87 | E4: =_xlfn.XLOOKUP($A4,'Cleaned - Medical Examinations'!$A$2:$A$2336,'Cleaned - Medical Examinations'!$D$2:$D$2336,0) -> Yes | F4: =_xlfn.XLOOKUP($A4,'Cleaned - Medical Examinations'!$A$2:$A$2336,'Cleaned - Medical Examinations'!$E$2:$E$2336,0) -> No | G4: =_xlfn.XLOOKUP($A4,'Cleaned - Medical Examinations'!$A$2:$A$2336,'Cleaned - Medical Examinations'!$F$2:$F$2336,0) -> No | H4: =_xlfn.XLOOKUP($A4,'Cleaned - Medical Examinations'!$A$2:$A$2336,'Cleaned - Medical Examinations'!$G$2:$G$2336,0) -> 2 | I4: =_xlfn.XLOOKUP($A4,'Cleaned - Medical Examinations'!$A$2:$A$2336,'Cleaned - Medical Examinations'!$H$2:$H$2336,0) -> Yes | J4: =_xlfn.XLOOKUP($A4,'Cleaned - Medical Examinations'!$A$2:$A$2336,'Cleaned - Medical Examinations'!$I$2:$I$2336,0) -> Obesity | K4: =IF(D4>=6.5,"Diabetic","Non-Diabetic") -> Diabetic | L4: =_xlfn.XLOOKUP($A4,'Cleaned - Hospitalisation Detai'!$A$2:$A$2344,'Cleaned - Hospitalisation Detai'!$J$2:$J$2344,0) -> 25822 | M4: =_xlfn.XLOOKUP($A4,'Cleaned - Hospitalisation Detai'!$A$2:$A$2344,'Cleaned - Hospitalisation Detai'!$F$2:$F$2344,0) -> 60021.4 | N4: =_xlfn.XLOOKUP($A4,'Cleaned - Hospitalisation Detai'!$A$2:$A$2344,'Cleaned - Hospitalisation Detai'!$G$2:$G$2344,0) -> tier - 1 | O4: =_xlfn.XLOOKUP($A4,'Cleaned - Hospitalisation Detai'!$A$2:$A$2344,'Cleaned - Hospitalisation Detai'!$H$2:$H$2344,0) -> tier - 1 | P4: =_xlfn.XLOOKUP($A4,'Cleaned - Hospitalisation Detai'!$A$2:$A$2344,'Cleaned - Hospitalisation Detai'!$I$2:$I$2344,0) -> R1012 | Q4: =_xlfn.XLOOKUP($A4,'Cleaned - Hospitalisation Detai'!$A$2:$A$2344,'Cleaned - Hospitalisation Detai'!$K$2:$K$2344,0) -> 52
A5: Id4 | B5: =_xlfn.XLOOKUP(A5,'Cleaned - Customer Names '!$A$2:$A$2336,'Cleaned - Customer Names '!$C$2:$C$2336,0) -> Kelsey | C5: =_xlfn.XLOOKUP($A5,'Cleaned - Medical Examinations'!$A$2:$A$2336,'Cleaned - Medical Examinations'!$B$2:$B$2336,0) -> 38.095 | D5: =_xlfn.XLOOKUP($A5,'Cleaned - Medical Examinations'!$A$2:$A$2336,'Cleaned - Medical Examinations'!$C$2:$C$2336,0) -> 6.05 | E5: =_xlfn.XLOOKUP($A5,'Cleaned - Medical Examinations'!$A$2:$A$2336,'Cleaned - Medical Examinations'!$D$2:$D$2336,0) -> No | F5: =_xlfn.XLOOKUP($A5,'Cleaned - Medical Examinations'!$A$2:$A$2336,'Cleaned - Medical Examinations'!$E$2:$E$2336,0) -> No | G5: =_xlfn.XLOOKUP($A5,'Cleaned - Medical Examinations'!$A$2:$A$2336,'Cleaned - Medical Examinations'!$F$2:$F$2336,0) -> No | H5: =_xlfn.XLOOKUP($A5,'Cleaned - Medical Examinations'!$A$2:$A$2336,'Cleaned - Medical Examinations'!$G$2:$G$2336,0) -> 0 | I5: =_xlfn.XLOOKUP($A5,'Cleaned - Medical Examinations'!$A$2:$A$2336,'Cleaned - Medical Examinations'!$H$2:$H$2336,0) -> Yes | J5: =_xlfn.XLOOKUP($A5,'Cleaned - Medical Examinations'!$A$2:$A$2336,'Cleaned - Medical Examinations'!$I$2:$I$2336,0) -> Obesity | K5: =IF(D5>=6.5,"Diabetic","Non-Diabetic") -> Non-Diabetic | L5: =_xlfn.XLOOKUP($A5,'Cleaned - Hospitalisation Detai'!$A$2:$A$2344,'Cleaned - Hospitalisation Detai'!$J$2:$J$2344,0) -> 33395 | M5: =_xlfn.XLOOKUP($A5,'Cleaned - Hospitalisation Detai'!$A$2:$A$2344,'Cleaned - Hospitalisation Detai'!$F$2:$F$2344,0) -> 58571.07 | N5: =_xlfn.XLOOKUP($A5,'Cleaned - Hospitalisation Detai'!$A$2:$A$2344,'Cleaned - Hospitalisation Detai'!$G$2:$G$2344,0) -> tier - 1 | O5: =_xlfn.XLOOKUP($A5,'Cleaned - Hospitalisation Detai'!$A$2:$A$2344,'Cleaned - Hospitalisation Detai'!$H$2:$H$2344,0) -> tier - 3 | P5: =_xlfn.XLOOKUP($A5,'Cleaned - Hospitalisation Detai'!$A$2:$A$2344,'Cleaned - Hospitalisation Detai'!$I$2:$I$2344,0) -> R1024 | Q5: =_xlfn.XLOOKUP($A5,'Cleaned - Hospitalisation Detai'!$A$2:$A$2344,'Cleaned - Hospitalisation Detai'!$K$2:$K$2344,0) -> 32
A6: Id5 | B6: =_xlfn.XLOOKUP(A6,'Cleaned - Customer Names '!$A$2:$A$2336,'Cleaned - Customer Names '!$C$2:$C$2336,0) -> Kristyn | C6: =_xlfn.XLOOKUP($A6,'Cleaned - Medical Examinations'!$A$2:$A$2336,'Cleaned - Medical Examinations'!$B$2:$B$2336,0) -> 35.53 | D6: =_xlfn.XLOOKUP($A6,'Cleaned - Medical Examinations'!$A$2:$A$2336,'Cleaned - Medical Examinations'!$C$2:$C$2336,0) -> 5.45 | E6: =_xlfn.XLOOKUP($A6,'Cleaned - Medical Examinations'!$A$2:$A$2336,'Cleaned - Medical Examinations'!$D$2:$D$2336,0) -> No | F6: =_xlfn.XLOOKUP($A6,'Cleaned - Medical Examinations'!$A$2:$A$2336,'Cleaned - Medical Examinations'!$E$2:$E$2336,0) -> No | G6: =_xlfn.XLOOKUP($A6,'Cleaned - Medical Examinations'!$A$2:$A$2336,'Cleaned - Medical Examinations'!$F$2:$F$2336,0) -> No | H6: =_xlfn.XLOOKUP($A6,'Cleaned - Medical Examinations'!$A$2:$A$2336,'Cleaned - Medical Examinations'!$G$2:$G$2336,0) -> 0 | I6: =_xlfn.XLOOKUP($A6,'Cleaned - Medical Examinations'!$A$2:$A$2336,'Cleaned - Medical Examinations'!$H$2:$H$2336,0) -> Yes | J6: =_xlfn.XLOOKUP($A6,'Cleaned - Medical Examinations'!$A$2:$A$2336,'Cleaned - Medical Examinations'!$I$2:$I$2336,0) -> Obesity | K6: =IF(D6>=6.5,"Diabetic","Non-Diabetic") -> Non-Diabetic | L6: =_xlfn.XLOOKUP($A6,'Cleaned - Hospitalisation Detai'!$A$2:$A$2344,'Cleaned - Hospitalisation Detai'!$J$2:$J$2344,0) -> 32678 | M6: =_xlfn.XLOOKUP($A6,'Cleaned - Hospitalisation Detai'!$A$2:$A$2344,'Cleaned - Hospitalisation Detai'!$F$2:$F$2344,0) -> 55135.4 | N6: =_xlfn.XLOOKUP($A6,'Cleaned - Hospitalisation Detai'!$A$2:$A$2344,'Cleaned - Hospitalisation Detai'!$G$2:$G$2344,0) -> tier - 1 | O6: =_xlfn.XLOOKUP($A6,'Cleaned - Hospitalisation Detai'!$A$2:$A$2344,'Cleaned - Hospitalisation Detai'!$H$2:$H$2344,0) -> tier - 2 | P6: =_xlfn.XLOOKUP($A6,'Cleaned - Hospitalisation Detai'!$A$2:$A$2344,'Cleaned - Hospitalisation Detai'!$I$2:$I$2344,0) -> R1012 | Q6: =_xlfn.XLOOKUP($A6,'Cleaned - Hospitalisation Detai'!$A$2:$A$2344,'Cleaned - Hospitalisation Detai'!$K$2:$K$2344,0) -> 33
A7: Id6 | B7: =_xlfn.XLOOKUP(A7,'Cleaned - Customer Names '!$A$2:$A$2336,'Cleaned - Customer Names '!$C$2:$C$2336,0) -> Russell B. | C7: =_xlfn.XLOOKUP($A7,'Cleaned - Medical Examinations'!$A$2:$A$2336,'Cleaned - Medical Examinations'!$B$2:$B$2336,0) -> 32.8 | D7: =_xlfn.XLOOKUP($A7,'Cleaned - Medical Examinations'!$A$2:$A$2336,'Cleaned - Medical Examinations'!$C$2:$C$2336,0) -> 6.59 | E7: =_xlfn.XLOOKUP($A7,'Cleaned - Medical Examinations'!$A$2:$A$2336,'Cleaned - Medical Examinations'!$D$2:$D$2336,0) -> No | F7: =_xlfn.XLOOKUP($A7,'Cleaned - Medical Examinations'!$A$2:$A$2336,'Cleaned - Medical Examinations'!$E$2:$E$2336,0) -> No | G7: =_xlfn.XLOOKUP($A7,'Cleaned - Medical Examinations'!$A$2:$A$2336,'Cleaned - Medical Examinations'!$F$2:$F$2336,0) -> No | H7: =_xlfn.XLOOKUP($A7,'Cleaned - Medical Examinations'!$A$2:$A$2336,'Cleaned - Medical Examinations'!$G$2:$G$2336,0) -> 0 | I7: =_xlfn.XLOOKUP($A7,'Cleaned - Medical Examinations'!$A$2:$A$2336,'Cleaned - Medical Examinations'!$H$2:$H$2336,0) -> Yes | J7: =_xlfn.XLOOKUP($A7,'Cleaned - Medical Examinations'!$A$2:$A$2336,'Cleaned - Medical Examinations'!$I$2:$I$2336,0) -> Obesity | K7: =IF(D7>=6.5,"Diabetic","Non-Diabetic") -> Diabetic | L7: =_xlfn.XLOOKUP($A7,'Cleaned - Hospitalisation Detai'!$A$2:$A$2344,'Cleaned - Hospitalisation Detai'!$J$2:$J$2344,0) -> 22862 | M7: =_xlfn.XLOOKUP($A7,'Cleaned - Hospitalisation Detai'!$A$2:$A$2344,'Cleaned - Hospitalisation Detai'!$F$2:$F$2344,0) -> 52590.83 | N7: =_xlfn.XLOOKUP($A7,'Cleaned - Hospitalisation Detai'!$A$2:$A$2344,'Cleaned - Hospitalisation Detai'!$G$2:$G$2344,0) -> tier - 1 | O7: =_xlfn.XLOOKUP($A7,'Cleaned - Hospitalisation Detai'!$A$2:$A$2344,'Cleaned - Hospitalisation Detai'!$H$2:$H$2344,0) -> tier - 3 | P7: =_xlfn.XLOOKUP($A7,'Cleaned - Hospitalisation Detai'!$A$2:$A$2344,'Cleaned - Hospitalisation Detai'!$I$2:$I$2344,0) -> R1011 | Q7: =_xlfn.XLOOKUP($A7,'Cleaned - Hospitalisation Detai'!$A$2:$A$2344,'Cleaned - Hospitalisation Detai'!$K$2:$K$2344,0) -> 60
A8: Id7 | B8: =_xlfn.XLOOKUP(A8,'Cleaned - Customer Names '!$A$2:$A$2336,'Cleaned - Customer Names '!$C$2:$C$2336,0) -> Scott | C8: =_xlfn.XLOOKUP($A8,'Cleaned - Medical Examinations'!$A$2:$A$2336,'Cleaned - Medical Examinations'!$B$2:$B$2336,0) -> 36.4 | D8: =_xlfn.XLOOKUP($A8,'Cleaned - Medical Examinations'!$A$2:$A$2336,'Cleaned - Medical Examinations'!$C$2:$C$2336,0) -> 6.07 | E8: =_xlfn.XLOOKUP($A8,'Cleaned - Medical Examinations'!$A$2:$A$2336,'Cleaned - Medical Examinations'!$D$2:$D$2336,0) -> No | F8: =_xlfn.XLOOKUP($A8,'Cleaned - Medical Examinations'!$A$2:$A$2336,'Cleaned - Medical Examinations'!$E$2:$E$2336,0) -> No | G8: =_xlfn.XLOOKUP($A8,'Cleaned - Medical Examinations'!$A$2:$A$2336,'Cleaned - Medical Examinations'!$F$2:$F$2336,0) -> No | H8: =_xlfn.XLOOKUP($A8,'Cleaned - Medical Examinations'!$A$2:$A$2336,'Cleaned - Medical Examinations'!$G$2:$G$2336,0) -> 0 | I8: =_xlfn.XLOOKUP($A8,'Cleaned - Medical Examinations'!$A$2:$A$2336,'Cleaned - Medical Examinations'!$H$2:$H$2336,0) -> Yes | J8: =_xlfn.XLOOKUP($A8,'Cleaned - Medical Examinations'!$A$2:$A$2336,'Cleaned - Medical Examinations'!$I$2:$I$2336,0) -> Obesity | K8: =IF(D8>=6.5,"Diabetic","Non-Diabetic") -> Non-Diabetic | L8: =_xlfn.XLOOKUP($A8,'Cleaned - Hospitalisation Detai'!$A$2:$A$2344,'Cleaned - Hospitalisation Detai'!$J$2:$J$2344,0) -> 34634 | M8: =_xlfn.XLOOKUP($A8,'Cleaned - Hospitalisation Detai'!$A$2:$A$2344,'Cleaned - Hospitalisation Detai'!$F$2:$F$2344,0) -> 51194.56 | N8: =_xlfn.XLOOKUP($A8,'Cleaned - Hospitalisation Detai'!$A$2:$A$2344,'Cleaned - Hospitalisation Detai'!$G$2:$G$2344,0) -> tier - 1 | O8: =_xlfn.XLOOKUP($A8,'Cleaned - Hospitalisation Detai'!$A$2:$A$2344,'Cleaned - Hospitalisation Detai'!$H$2:$H$2344,0) -> tier - 3 | P8: =_xlfn.XLOOKUP($A8,'Cleaned - Hospitalisation Detai'!$A$2:$A$2344,'Cleaned - Hospitalisation Detai'!$I$2:$I$2344,0) -> R1011 | Q8: =_xlfn.XLOOKUP($A8,'Cleaned - Hospitalisation Detai'!$A$2:$A$2344,'Cleaned - Hospitalisation Detai'!$K$2:$K$2344,0) -> 28
A9: Id8 | B9: =_xlfn.XLOOKUP(A9,'Cleaned - Customer Names '!$A$2:$A$2336,'Cleaned - Customer Names '!$C$2:$C$2336,0) -> Stephen | C9: =_xlfn.XLOOKUP($A9,'Cleaned - Medical Examinations'!$A$2:$A$2336,'Cleaned - Medical Examinations'!$B$2:$B$2336,0) -> 36.96 | D9: =_xlfn.XLOOKUP($A9,'Cleaned - Medical Examinations'!$A$2:$A$2336,'Cleaned - Medical Examinations'!$C$2:$C$2336,0) -> 7.93 | E9: =_xlfn.XLOOKUP($A9,'Cleaned - Medical Examinations'!$A$2:$A$2336,'Cleaned - Medical Examinations'!$D$2:$D$2336,0) -> No | F9: =_xlfn.XLOOKUP($A9,'Cleaned - Medical Examinations'!$A$2:$A$2336,'Cleaned - Medical Examinations'!$E$2:$E$2336,0) -> No | G9: =_xlfn.XLOOKUP($A9,'Cleaned - Medical Examinations'!$A$2:$A$2336,'Cleaned - Medical Examinations'!$F$2:$F$2336,0) -> No | H9: =_xlfn.XLOOKUP($A9,'Cleaned - Medical Examinations'!$A$2:$A$2336,'Cleaned - Medical Examinations'!$G$2:$G$2336,0) -> 3 | I9: =_xlfn.XLOOKUP($A9,'Cleaned - Medical Examinations'!$A$2:$A$2336,'Cleaned - Medical Examinations'!$H$2:$H$2336,0) -> Yes | J9: =_xlfn.XLOOKUP($A9,'Cleaned - Medical Examinations'!$A$2:$A$2336,'Cleaned - Medical Examinations'!$I$2:$I$2336,0) -> Obesity | K9: =IF(D9>=6.5,"Diabetic","Non-Diabetic") -> Diabetic | L9: =_xlfn.XLOOKUP($A9,'Cleaned - Hospitalisation Detai'!$A$2:$A$2344,'Cleaned - Hospitalisation Detai'!$J$2:$J$2344,0) -> 21363 | M9: =_xlfn.XLOOKUP($A9,'Cleaned - Hospitalisation Detai'!$A$2:$A$2344,'Cleaned - Hospitalisation Detai'!$F$2:$F$2344,0) -> 49577.66 | N9: =_xlfn.XLOOKUP($A9,'Cleaned - Hospitalisation Detai'!$A$2:$A$2344,'Cleaned - Hospitalisation Detai'!$G$2:$G$2344,0) -> tier - 2 | O9: =_xlfn.XLOOKUP($A9,'Cleaned - Hospitalisation Detai'!$A$2:$A$2344,'Cleaned - Hospitalisation Detai'!$H$2:$H$2344,0) -> tier - 2 | P9: =_xlfn.XLOOKUP($A9,'Cleaned - Hospitalisation Detai'!$A$2:$A$2344,'Cleaned - Hospitalisation Detai'!$I$2:$I$2344,0) -> R1013 | Q9: =_xlfn.XLOOKUP($A9,'Cleaned - Hospitalisation Detai'!$A$2:$A$2344,'Cleaned - Hospitalisation Detai'!$K$2:$K$2344,0) -> 64
A10: Id9 | B10: =_xlfn.XLOOKUP(A10,'Cleaned - Customer Names '!$A$2:$A$2336,'Cleaned - Customer Names '!$C$2:$C$2336,0) -> Patrick R. | C10: =_xlfn.XLOOKUP($A10,'Cleaned - Medical Examinations'!$A$2:$A$2336,'Cleaned - Medical Examinations'!$B$2:$B$2336,0) -> 41.14 | D10: =_xlfn.XLOOKUP($A10,'Cleaned - Medical Examinations'!$A$2:$A$2336,'Cleaned - Medical Examinations'!$C$2:$C$2336,0) -> 9.58 | E10: =_xlfn.XLOOKUP($A10,'Cleaned - Medical Examinations'!$A$2:$A$2336,'Cleaned - Medical Examinations'!$D$2:$D$2336,0) -> Yes | F10: =_xlfn.XLOOKUP($A10,'Cleaned - Medical Examinations'!$A$2:$A$2336,'Cleaned - Medical Examinations'!$E$2:$E$2336,0) -> No | G10: =_xlfn.XLOOKUP($A10,'Cleaned - Medical Examinations'!$A$2:$A$2336,'Cleaned - Medical Examinations'!$F$2:$F$2336,0) -> Yes | H10: =_xlfn.XLOOKUP($A10,'Cleaned - Medical Examinations'!$A$2:$A$2336,'Cleaned - Medical Examinations'!$G$2:$G$2336,0) -> 1 | I10: =_xlfn.XLOOKUP($A10,'Cleaned - Medical Examinations'!$A$2:$A$2336,'Cleaned - Medical Examinations'!$H$2:$H$2336,0) -> Yes | J10: =_xlfn.XLOOKUP($A10,'Cleaned - Medical Examinations'!$A$2:$A$2336,'Cleaned - Medical Examinations'!$I$2:$I$2336,0) -> Obesity | K10: =IF(D10>=6.5,"Diabetic","Non-Diabetic") -> Diabetic | L10: =_xlfn.XLOOKUP($A10,'Cleaned - Hospitalisation Detai'!$A$2:$A$2344,'Cleaned - Hospitalisation Detai'!$J$2:$J$2344,0) -> 23258 | M10: =_xlfn.XLOOKUP($A10,'Cleaned - Hospitalisation Detai'!$A$2:$A$2344,'Cleaned - Hospitalisation Detai'!$F$2:$F$2344,0) -> 48970.25 | N10: =_xlfn.XLOOKUP($A10,'Cleaned - Hospitalisation Detai'!$A$2:$A$2344,'Cleaned - Hospitalisation Detai'!$G$2:$G$2344,0) -> tier - 1 | O10: =_xlfn.XLOOKUP($A10,'Cleaned - Hospitalisation Detai'!$A$2:$A$2344,'Cleaned - Hospitalisation Detai'!$H$2:$H$2344,0) -> tier - 2 | P10: =_xlfn.XLOOKUP($A10,'Cleaned - Hospitalisation Detai'!$A$2:$A$2344,'Cleaned - Hospitalisation Detai'!$I$2:$I$2344,0) -> R1013 | Q10: =_xlfn.XLOOKUP($A10,'Cleaned - Hospitalisation Detai'!$A$2:$A$2344,'Cleaned - Hospitalisation Detai'!$K$2:$K$2344,0) -> 59
A11: Id10 | B11: =_xlfn.XLOOKUP(A11,'Cleaned - Customer Names '!$A$2:$A$2336,'Cleaned - Customer Names '!$C$2:$C$2336,0) -> Brooke N. | C11: =_xlfn.XLOOKUP($A11,'Cleaned - Medical Examinations'!$A$2:$A$2336,'Cleaned - Medical Examinations'!$B$2:$B$2336,0) -> 38.06 | D11: =_xlfn.XLOOKUP($A11,'Cleaned - Medical Examinations'!$A$2:$A$2336,'Cleaned - Medical Examinations'!$C$2:$C$2336,0) -> 10.79 | E11: =_xlfn.XLOOKUP($A11,'Cleaned - Medical Examinations'!$A$2:$A$2336,'Cleaned - Medical Examinations'!$D$2:$D$2336,0) -> No | F11: =_xlfn.XLOOKUP($A11,'Cleaned - Medical Examinations'!$A$2:$A$2336,'Cleaned - Medical Examinations'!$E$2:$E$2336,0) -> No | G11: =_xlfn.XLOOKUP($A11,'Cleaned - Medical Examinations'!$A$2:$A$2336,'Cleaned - Medical Examinations'!$F$2:$F$2336,0) -> No | H11: =_xlfn.XLOOKUP($A11,'Cleaned - Medical Examinations'!$A$2:$A$2336,'Cleaned - Medical Examinations'!$G$2:$G$2336,0) -> 0 | I11: =_xlfn.XLOOKUP($A11,'Cleaned - Medical Examinations'!$A$2:$A$2336,'Cleaned - Medical Examinations'!$H$2:$H$2336,0) -> Yes | J11: =_xlfn.XLOOKUP($A11,'Cleaned - Medical Examinations'!$A$2:$A$2336,'Cleaned - Medical Examinations'!$I$2:$I$2336,0) -> Obesity | K11: =IF(D11>=6.5,"Diabetic","Non-Diabetic") -> Diabetic | L11: =_xlfn.XLOOKUP($A11,'Cleaned - Hospitalisation Detai'!$A$2:$A$2344,'Cleaned - Hospitalisation Detai'!$J$2:$J$2344,0) -> 28853 | M11: =_xlfn.XLOOKUP($A11,'Cleaned - Hospitalisation Detai'!$A$2:$A$2344,'Cleaned - Hospitalisation Detai'!$F$2:$F$2344,0) -> 48885.14 | N11: =_xlfn.XLOOKUP($A11,'Cleaned - Hospitalisation Detai'!$A$2:$A$2344,'Cleaned - Hospitalisation Detai'!$G$2:$G$2344,0) -> tier - 1 | O11: =_xlfn.XLOOKUP($A11,'Cleaned - Hospitalisation Detai'!$A$2:$A$2344,'Cleaned - Hospitalisation Detai'!$H$2:$H$2344,0) -> tier - 2 | P11: =_xlfn.XLOOKUP($A11,'Cleaned - Hospitalisation Detai'!$A$2:$A$2344,'Cleaned - Hospitalisation Detai'!$I$2:$I$2344,0) -> R1013 | Q11: =_xlfn.XLOOKUP($A11,'Cleaned - Hospitalisation Detai'!$A$2:$A$2344,'Cleaned - Hospitalisation Detai'!$K$2:$K$2344,0) -> 44
A12: Id11 | B12: =_xlfn.XLOOKUP(A12,'Cleaned - Customer Names '!$A$2:$A$2336,'Cleaned - Customer Names '!$C$2:$C$2336,0) -> Paola Andrea | C12: =_xlfn.XLOOKUP($A12,'Cleaned - Medical Examinations'!$A$2:$A$2336,'Cleaned - Medical Examinations'!$B$2:$B$2336,0) -> 37.7 | D12: =_xlfn.XLOOKUP($A12,'Cleaned - Medical Examinations'!$A$2:$A$2336,'Cleaned - Medical Examinations'!$C$2:$C$2336,0) -> 5.96 | E12: =_xlfn.XLOOKUP($A12,'Cleaned - Medical Examinations'!$A$2:$A$2336,'Cleaned - Medical Examinations'!$D$2:$D$2336,0) -> Yes | F12: =_xlfn.XLOOKUP($A12,'Cleaned - Medical Examinations'!$A$2:$A$2336,'Cleaned - Medical Examinations'!$E$2:$E$2336,0) -> No | G12: =_xlfn.XLOOKUP($A12,'Cleaned - Medical Examinations'!$A$2:$A$2336,'Cleaned - Medical Examinations'!$F$2:$F$2336,0) -> No | H12: =_xlfn.XLOOKUP($A12,'Cleaned - Medical Examinations'!$A$2:$A$2336,'Cleaned - Medical Examinations'!$G$2:$G$2336,0) -> 2 | I12: =_xlfn.XLOOKUP($A12,'Cleaned - Medical Examinations'!$A$2:$A$2336,'Cleaned - Medical Examinations'!$H$2:$H$2336,0) -> Yes | J12: =_xlfn.XLOOKUP($A12,'Cleaned - Medical Examinations'!$A$2:$A$2336,'Cleaned - Medical Examinations'!$I$2:$I$2336,0) -> Obesity | K12: =IF(D12>=6.5,"Diabetic","Non-Diabetic") -> Non-Diabetic | L12: =_xlfn.XLOOKUP($A12,'Cleaned - Hospitalisation Detai'!$A$2:$A$2344,'Cleaned - Hospitalisation Detai'!$J$2:$J$2344,0) -> 21753 | M12: =_xlfn.XLOOKUP($A12,'Cleaned - Hospitalisation Detai'!$A$2:$A$2344,'Cleaned - Hospitalisation Detai'!$F$2:$F$2344,0) -> 48824.45 | N12: =_xlfn.XLOOKUP($A12,'Cleaned - Hospitalisation Detai'!$A$2:$A$2344,'Cleaned - Hospitalisation Detai'!$G$2:$G$2344,0) -> tier - 2 | O12: =_xlfn.XLOOKUP($A12,'Cleaned - Hospitalisation Detai'!$A$2:$A$2344,'Cleaned - Hospitalisation Detai'!$H$2:$H$2344,0) -> tier - 1 | P12: =_xlfn.XLOOKUP($A12,'Cleaned - Hospitalisation Detai'!$A$2:$A$2344,'Cleaned - Hospitalisation Detai'!$I$2:$I$2344,0) -> R1011 | Q12: =_xlfn.XLOOKUP($A12,'Cleaned - Hospitalisation Detai'!$A$2:$A$2344,'Cleaned - Hospitalisation Detai'!$K$2:$K$2344,0) -> 63
A13: Id12 | B13: =_xlfn.XLOOKUP(A13,'Cleaned - Customer Names '!$A$2:$A$2336,'Cleaned - Customer Names '!$C$2:$C$2336,0) -> David | C13: =_xlfn.XLOOKUP($A13,'Cleaned - Medical Examinations'!$A$2:$A$2336,'Cleaned - Medical Examinations'!$B$2:$B$2336,0) -> 42.13 | D13: =_xlfn.XLOOKUP($A13,'Cleaned - Medical Examinations'!$A$2:$A$2336,'Cleaned - Medical Examinations'!$C$2:$C$2336,0) -> 11.9 | E13: =_xlfn.XLOOKUP($A13,'Cleaned - Medical Examinations'!$A$2:$A$2336,'Cleaned - Medical Examinations'!$D$2:$D$2336,0) -> No | F13: =_xlfn.XLOOKUP($A13,'Cleaned - Medical Examinations'!$A$2:$A$2336,'Cleaned - Medical Examinations'!$E$2:$E$2336,0) -> No | G13: =_xlfn.XLOOKUP($A13,'Cleaned - Medical Examinations'!$A$2:$A$2336,'Cleaned - Medical Examinations'!$F$2:$F$2336,0) -> No | H13: =_xlfn.XLOOKUP($A13,'Cleaned - Medical Examinations'!$A$2:$A$2336,'Cleaned - Medical Examinations'!$G$2:$G$2336,0) -> 0 | I13: =_xlfn.XLOOKUP($A13,'Cleaned - Medical Examinations'!$A$2:$A$2336,'Cleaned - Medical Examinations'!$H$2:$H$2336,0) -> Yes | J13: =_xlfn.XLOOKUP($A13,'Cleaned - Medical Examinations'!$A$2:$A$2336,'Cleaned - Medical Examinations'!$I$2:$I$2336,0) -> Obesity | K13: =IF(D13>=6.5,"Diabetic","Non-Diabetic") -> Diabetic | L13: =_xlfn.XLOOKUP($A13,'Cleaned - Hospitalisation Detai'!$A$2:$A$2344,'Cleaned - Hospitalisation Detai'!$J$2:$J$2344,0) -> 24042 | M13: =_xlfn.XLOOKUP($A13,'Cleaned - Hospitalisation Detai'!$A$2:$A$2344,'Cleaned - Hospitalisation Detai'!$F$2:$F$2344,0) -> 48675.52 | N13: =_xlfn.XLOOKUP($A13,'Cleaned - Hospitalisation Detai'!$A$2:$A$2344,'Cleaned - Hospitalisation Detai'!$G$2:$G$2344,0) -> tier - 1 | O13: =_xlfn.XLOOKUP($A13,'Cleaned - Hospitalisation Detai'!$A$2:$A$2344,'Cleaned - Hospitalisation Detai'!$H$2:$H$2344,0) -> tier - 2 | P13: =_xlfn.XLOOKUP($A13,'Cleaned - Hospitalisation Detai'!$A$2:$A$2344,'Cleaned - Hospitalisation Detai'!$I$2:$I$2344,0) -> R1013 | Q13: =_xlfn.XLOOKUP($A13,'Cleaned - Hospitalisation Detai'!$A$2:$A$2344,'Cleaned - Hospitalisation Detai'!$K$2:$K$2344,0) -> 57
... A2336: Id2335 | B2336: =_xlfn.XLOOKUP(A2336,'Cleaned - Customer Names '!$A$2:$A$2336,'Cleaned - Customer Names '!$C$2:$C$2336,0) -> Aaron K | C2336: =_xlfn.XLOOKUP($A2336,'Cleaned - Medical Examinations'!$A$2:$A$2336,'Cleaned - Medical Examinations'!$B$2:$B$2336,0) -> 17.58 | D2336: =_xlfn.XLOOKUP($A2336,'Cleaned - Medical Examinations'!$A$2:$A$2336,'Cleaned - Medical Examinations'!$C$2:$C$2336,0) -> 4.51 | E2336: =_xlfn.XLOOKUP($A2336,'Cleaned - Medical Examinations'!$A$2:$A$2336,'Cleaned - Medical Examinations'!$D$2:$D$2336,0) -> No | F2336: =_xlfn.XLOOKUP($A2336,'Cleaned - Medical Examinations'!$A$2:$A$2336,'Cleaned - Medical Examinations'!$E$2:$E$2336,0) -> No | G2336: =_xlfn.XLOOKUP($A2336,'Cleaned - Medical Examinations'!$A$2:$A$2336,'Cleaned - Medical Examinations'!$F$2:$F$2336,0) -> No | H2336: =_xlfn.XLOOKUP($A2336,'Cleaned - Medical Examinations'!$A$2:$A$2336,'Cleaned - Medical Examinations'!$G$2:$G$2336,0) -> 1 | I2336: =_xlfn.XLOOKUP($A2336,'Cleaned - Medical Examinations'!$A$2:$A$2336,'Cleaned - Medical Examinations'!$H$2:$H$2336,0) -> No | J2336: =_xlfn.XLOOKUP($A2336,'Cleaned - Medical Examinations'!$A$2:$A$2336,'Cleaned - Medical Examinations'!$I$2:$I$2336,0) -> Underweight | K2336: =IF(D2336>=6.5,"Diabetic","Non-Diabetic") -> Non-Diabetic | L2336: =_xlfn.XLOOKUP($A2336,'Cleaned - Hospitalisation Detai'!$A$2:$A$2344,'Cleaned - Hospitalisation Detai'!$J$2:$J$2344,0) -> 33794 | M2336: =_xlfn.XLOOKUP($A2336,'Cleaned - Hospitalisation Detai'!$A$2:$A$2344,'Cleaned - Hospitalisation Detai'!$F$2:$F$2344,0) -> 563.84 | N2336: =_xlfn.XLOOKUP($A2336,'Cleaned - Hospitalisation Detai'!$A$2:$A$2344,'Cleaned - Hospitalisation Detai'!$G$2:$G$2344,0) -> tier - 2 | O2336: =_xlfn.XLOOKUP($A2336,'Cleaned - Hospitalisation Detai'!$A$2:$A$2344,'Cleaned - Hospitalisation Detai'!$H$2:$H$2344,0) -> tier - 3 | P2336: =_xlfn.XLOOKUP($A2336,'Cleaned - Hospitalisation Detai'!$A$2:$A$2344,'Cleaned - Hospitalisation Detai'!$I$2:$I$2344,0) -> R1013 | Q2336: =_xlfn.XLOOKUP($A2336,'Cleaned - Hospitalisation Detai'!$A$2:$A$2344,'Cleaned - Hospitalisation Detai'!$K$2:$K$2344,0) -> 30

Sheet New - Health Care
A1: Customer ID | B1: First Name | C1: BMI | D1: HBA1C | E1: Heart Issues | F1: Any Transplants | G1: Cancer History | H1: Number of Major Surgeries | I1: Smoker | J1: Weight Status | K1: Diabetes Status | L1: Date of Birth | M1: Charges | N1: Hospital Tier | O1: City Tier | P1: State ID | Q1: Age
A2: Id1 | B2: =_xlfn.XLOOKUP(A2,'Cleaned - Customer Names '!$A$2:$A$2336,'Cleaned - Customer Names '!$C$2:$C$2336,0) -> Kelly | C2: =_xlfn.XLOOKUP($A2,'Cleaned - Medical Examinations'!$A$2:$A$2336,'Cleaned - Medical Examinations'!$B$2:$B$2336,0) -> 47.41 | D2: =_xlfn.XLOOKUP($A2,'Cleaned - Medical Examinations'!$A$2:$A$2336,'Cleaned - Medical Examinations'!$C$2:$C$2336,0) -> 7.47 | E2: =_xlfn.XLOOKUP($A2,'Cleaned - Medical Examinations'!$A$2:$A$2336,'Cleaned - Medical Examinations'!$D$2:$D$2336,0) -> No | F2: =_xlfn.XLOOKUP($A2,'Cleaned - Medical Examinations'!$A$2:$A$2336,'Cleaned - Medical Examinations'!$E$2:$E$2336,0) -> No | G2: =_xlfn.XLOOKUP($A2,'Cleaned - Medical Examinations'!$A$2:$A$2336,'Cleaned - Medical Examinations'!$F$2:$F$2336,0) -> No | H2: =_xlfn.XLOOKUP($A2,'Cleaned - Medical Examinations'!$A$2:$A$2336,'Cleaned - Medical Examinations'!$G$2:$G$2336,0) -> 0 | I2: =_xlfn.XLOOKUP($A2,'Cleaned - Medical Examinations'!$A$2:$A$2336,'Cleaned - Medical Examinations'!$H$2:$H$2336,0) -> Yes | J2: =_xlfn.XLOOKUP($A2,'Cleaned - Medical Examinations'!$A$2:$A$2336,'Cleaned - Medical Examinations'!$I$2:$I$2336,0) -> Obesity | K2: =IF(D2>=6.5,"Diabetic","Non-Diabetic") -> Diabetic | L2: =_xlfn.XLOOKUP($A2,'Cleaned - Hospitalisation Detai'!$A$2:$A$2344,'Cleaned - Hospitalisation Detai'!$J$2:$J$2344,0) -> 25123 | M2: =_xlfn.XLOOKUP($A2,'Cleaned - Hospitalisation Detai'!$A$2:$A$2344,'Cleaned - Hospitalisation Detai'!$F$2:$F$2344,0) -> 63770.43 | N2: =_xlfn.XLOOKUP($A2,'Cleaned - Hospitalisation Detai'!$A$2:$A$2344,'Cleaned - Hospitalisation Detai'!$G$2:$G$2344,0) -> tier - 1 | O2: =_xlfn.XLOOKUP($A2,'Cleaned - Hospitalisation Detai'!$A$2:$A$2344,'Cleaned - Hospitalisation Detai'!$H$2:$H$2344,0) -> tier - 3 | P2: =_xlfn.XLOOKUP($A2,'Cleaned - Hospitalisation Detai'!$A$2:$A$2344,'Cleaned - Hospitalisation Detai'!$I$2:$I$2344,0) -> R1013 | Q2: =_xlfn.XLOOKUP($A2,'Cleaned - Hospitalisation Detai'!$A$2:$A$2344,'Cleaned - Hospitalisation Detai'!$K$2:$K$2344,0) -> 54
A3: Id2 | B3: =_xlfn.XLOOKUP(A3,'Cleaned - Customer Names '!$A$2:$A$2336,'Cleaned - Customer Names '!$C$2:$C$2336,0) -> Matthew D | C3: =_xlfn.XLOOKUP($A3,'Cleaned - Medical Examinations'!$A$2:$A$2336,'Cleaned - Medical Examinations'!$B$2:$B$2336,0) -> 30.36 | D3: =_xlfn.XLOOKUP($A3,'Cleaned - Medical Examinations'!$A$2:$A$2336,'Cleaned - Medical Examinations'!$C$2:$C$2336,0) -> 5.77 | E3: =_xlfn.XLOOKUP($A3,'Cleaned - Medical Examinations'!$A$2:$A$2336,'Cleaned - Medical Examinations'!$D$2:$D$2336,0) -> No | F3: =_xlfn.XLOOKUP($A3,'Cleaned - Medical Examinations'!$A$2:$A$2336,'Cleaned - Medical Examinations'!$E$2:$E$2336,0) -> No | G3: =_xlfn.XLOOKUP($A3,'Cleaned - Medical Examinations'!$A$2:$A$2336,'Cleaned - Medical Examinations'!$F$2:$F$2336,0) -> No | H3: =_xlfn.XLOOKUP($A3,'Cleaned - Medical Examinations'!$A$2:$A$2336,'Cleaned - Medical Examinations'!$G$2:$G$2336,0) -> 0 | I3: =_xlfn.XLOOKUP($A3,'Cleaned - Medical Examinations'!$A$2:$A$2336,'Cleaned - Medical Examinations'!$H$2:$H$2336,0) -> Yes | J3: =_xlfn.XLOOKUP($A3,'Cleaned - Medical Examinations'!$A$2:$A$2336,'Cleaned - Medical Examinations'!$I$2:$I$2336,0) -> Obesity | K3: =IF(D3>=6.5,"Diabetic","Non-Diabetic") -> Non-Diabetic | L3: =_xlfn.XLOOKUP($A3,'Cleaned - Hospitalisation Detai'!$A$2:$A$2344,'Cleaned - Hospitalisation Detai'!$J$2:$J$2344,0) -> 28284 | M3: =_xlfn.XLOOKUP($A3,'Cleaned - Hospitalisation Detai'!$A$2:$A$2344,'Cleaned - Hospitalisation Detai'!$F$2:$F$2344,0) -> 62592.87 | N3: =_xlfn.XLOOKUP($A3,'Cleaned - Hospitalisation Detai'!$A$2:$A$2344,'Cleaned - Hospitalisation Detai'!$G$2:$G$2344,0) -> tier - 2 | O3: =_xlfn.XLOOKUP($A3,'Cleaned - Hospitalisation Detai'!$A$2:$A$2344,'Cleaned - Hospitalisation Detai'!$H$2:$H$2344,0) -> tier - 3 | P3: =_xlfn.XLOOKUP($A3,'Cleaned - Hospitalisation Detai'!$A$2:$A$2344,'Cleaned - Hospitalisation Detai'!$I$2:$I$2344,0) -> R1013 | Q3: =_xlfn.XLOOKUP($A3,'Cleaned - Hospitalisation Detai'!$A$2:$A$2344,'Cleaned - Hospitalisation Detai'!$K$2:$K$2344,0) -> 46
A4: Id3 | B4: =_xlfn.XLOOKUP(A4,'Cleaned - Customer Names '!$A$2:$A$2336,'Cleaned - Customer Names '!$C$2:$C$2336,0) -> Phil | C4: =_xlfn.XLOOKUP($A4,'Cleaned - Medical Examinations'!$A$2:$A$2336,'Cleaned - Medical Examinations'!$B$2:$B$2336,0) -> 34.485 | D4: =_xlfn.XLOOKUP($A4,'Cleaned - Medical Examinations'!$A$2:$A$2336,'Cleaned - Medical Examinations'!$C$2:$C$2336,0) -> 11.87 | E4: =_xlfn.XLOOKUP($A4,'Cleaned - Medical Examinations'!$A$2:$A$2336,'Cleaned - Medical Examinations'!$D$2:$D$2336,0) -> Yes | F4: =_xlfn.XLOOKUP($A4,'Cleaned - Medical Examinations'!$A$2:$A$2336,'Cleaned - Medical Examinations'!$E$2:$E$2336,0) -> No | G4: =_xlfn.XLOOKUP($A4,'Cleaned - Medical Examinations'!$A$2:$A$2336,'Cleaned - Medical Examinations'!$F$2:$F$2336,0) -> No | H4: =_xlfn.XLOOKUP($A4,'Cleaned - Medical Examinations'!$A$2:$A$2336,'Cleaned - Medical Examinations'!$G$2:$G$2336,0) -> 2 | I4: =_xlfn.XLOOKUP($A4,'Cleaned - Medical Examinations'!$A$2:$A$2336,'Cleaned - Medical Examinations'!$H$2:$H$2336,0) -> Yes | J4: =_xlfn.XLOOKUP($A4,'Cleaned - Medical Examinations'!$A$2:$A$2336,'Cleaned - Medical Examinations'!$I$2:$I$2336,0) -> Obesity | K4: =IF(D4>=6.5,"Diabetic","Non-Diabetic") -> Diabetic | L4: =_xlfn.XLOOKUP($A4,'Cleaned - Hospitalisation Detai'!$A$2:$A$2344,'Cleaned - Hospitalisation Detai'!$J$2:$J$2344,0) -> 25822 | M4: =_xlfn.XLOOKUP($A4,'Cleaned - Hospitalisation Detai'!$A$2:$A$2344,'Cleaned - Hospitalisation Detai'!$F$2:$F$2344,0) -> 60021.4 | N4: =_xlfn.XLOOKUP($A4,'Cleaned - Hospitalisation Detai'!$A$2:$A$2344,'Cleaned - Hospitalisation Detai'!$G$2:$G$2344,0) -> tier - 1 | O4: =_xlfn.XLOOKUP($A4,'Cleaned - Hospitalisation Detai'!$A$2:$A$2344,'Cleaned - Hospitalisation Detai'!$H$2:$H$2344,0) -> tier - 1 | P4: =_xlfn.XLOOKUP($A4,'Cleaned - Hospitalisation Detai'!$A$2:$A$2344,'Cleaned - Hospitalisation Detai'!$I$2:$I$2344,0) -> R1012 | Q4: =_xlfn.XLOOKUP($A4,'Cleaned - Hospitalisation Detai'!$A$2:$A$2344,'Cleaned - Hospitalisation Detai'!$K$2:$K$2344,0) -> 52
A5: Id4 | B5: =_xlfn.XLOOKUP(A5,'Cleaned - Customer Names '!$A$2:$A$2336,'Cleaned - Customer Names '!$C$2:$C$2336,0) -> Kelsey | C5: =_xlfn.XLOOKUP($A5,'Cleaned - Medical Examinations'!$A$2:$A$2336,'Cleaned - Medical Examinations'!$B$2:$B$2336,0) -> 38.095 | D5: =_xlfn.XLOOKUP($A5,'Cleaned - Medical Examinations'!$A$2:$A$2336,'Cleaned - Medical Examinations'!$C$2:$C$2336,0) -> 6.05 | E5: =_xlfn.XLOOKUP($A5,'Cleaned - Medical Examinations'!$A$2:$A$2336,'Cleaned - Medical Examinations'!$D$2:$D$2336,0) -> No | F5: =_xlfn.XLOOKUP($A5,'Cleaned - Medical Examinations'!$A$2:$A$2336,'Cleaned - Medical Examinations'!$E$2:$E$2336,0) -> No | G5: =_xlfn.XLOOKUP($A5,'Cleaned - Medical Examinations'!$A$2:$A$2336,'Cleaned - Medical Examinations'!$F$2:$F$2336,0) -> No | H5: =_xlfn.XLOOKUP($A5,'Cleaned - Medical Examinations'!$A$2:$A$2336,'Cleaned - Medical Examinations'!$G$2:$G$2336,0) -> 0 | I5: =_xlfn.XLOOKUP($A5,'Cleaned - Medical Examinations'!$A$2:$A$2336,'Cleaned - Medical Examinations'!$H$2:$H$2336,0) -> Yes | J5: =_xlfn.XLOOKUP($A5,'Cleaned - Medical Examinations'!$A$2:$A$2336,'Cleaned - Medical Examinations'!$I$2:$I$2336,0) -> Obesity | K5: =IF(D5>=6.5,"Diabetic","Non-Diabetic") -> Non-Diabetic | L5: =_xlfn.XLOOKUP($A5,'Cleaned - Hospitalisation Detai'!$A$2:$A$2344,'Cleaned - Hospitalisation Detai'!$J$2:$J$2344,0) -> 33395 | M5: =_xlfn.XLOOKUP($A5,'Cleaned - Hospitalisation Detai'!$A$2:$A$2344,'Cleaned - Hospitalisation Detai'!$F$2:$F$2344,0) -> 58571.07 | N5: =_xlfn.XLOOKUP($A5,'Cleaned - Hospitalisation Detai'!$A$2:$A$2344,'Cleaned - Hospitalisation Detai'!$G$2:$G$2344,0) -> tier - 1 | O5: =_xlfn.XLOOKUP($A5,'Cleaned - Hospitalisation Detai'!$A$2:$A$2344,'Cleaned - Hospitalisation Detai'!$H$2:$H$2344,0) -> tier - 3 | P5: =_xlfn.XLOOKUP($A5,'Cleaned - Hospitalisation Detai'!$A$2:$A$2344,'Cleaned - Hospitalisation Detai'!$I$2:$I$2344,0) -> R1024 | Q5: =_xlfn.XLOOKUP($A5,'Cleaned - Hospitalisation Detai'!$A$2:$A$2344,'Cleaned - Hospitalisation Detai'!$K$2:$K$2344,0) -> 32
A6: Id5 | B6: =_xlfn.XLOOKUP(A6,'Cleaned - Customer Names '!$A$2:$A$2336,'Cleaned - Customer Names '!$C$2:$C$2336,0) -> Kristyn | C6: =_xlfn.XLOOKUP($A6,'Cleaned - Medical Examinations'!$A$2:$A$2336,'Cleaned - Medical Examinations'!$B$2:$B$2336,0) -> 35.53 | D6: =_xlfn.XLOOKUP($A6,'Cleaned - Medical Examinations'!$A$2:$A$2336,'Cleaned - Medical Examinations'!$C$2:$C$2336,0) -> 5.45 | E6: =_xlfn.XLOOKUP($A6,'Cleaned - Medical Examinations'!$A$2:$A$2336,'Cleaned - Medical Examinations'!$D$2:$D$2336,0) -> No | F6: =_xlfn.XLOOKUP($A6,'Cleaned - Medical Examinations'!$A$2:$A$2336,'Cleaned - Medical Examinations'!$E$2:$E$2336,0) -> No | G6: =_xlfn.XLOOKUP($A6,'Cleaned - Medical Examinations'!$A$2:$A$2336,'Cleaned - Medical Examinations'!$F$2:$F$2336,0) -> No | H6: =_xlfn.XLOOKUP($A6,'Cleaned - Medical Examinations'!$A$2:$A$2336,'Cleaned - Medical Examinations'!$G$2:$G$2336,0) -> 0 | I6: =_xlfn.XLOOKUP($A6,'Cleaned - Medical Examinations'!$A$2:$A$2336,'Cleaned - Medical Examinations'!$H$2:$H$2336,0) -> Yes | J6: =_xlfn.XLOOKUP($A6,'Cleaned - Medical Examinations'!$A$2:$A$2336,'Cleaned - Medical Examinations'!$I$2:$I$2336,0) -> Obesity | K6: =IF(D6>=6.5,"Diabetic","Non-Diabetic") -> Non-Diabetic | L6: =_xlfn.XLOOKUP($A6,'Cleaned - Hospitalisation Detai'!$A$2:$A$2344,'Cleaned - Hospitalisation Detai'!$J$2:$J$2344,0) -> 32678 | M6: =_xlfn.XLOOKUP($A6,'Cleaned - Hospitalisation Detai'!$A$2:$A$2344,'Cleaned - Hospitalisation Detai'!$F$2:$F$2344,0) -> 55135.4 | N6: =_xlfn.XLOOKUP($A6,'Cleaned - Hospitalisation Detai'!$A$2:$A$2344,'Cleaned - Hospitalisation Detai'!$G$2:$G$2344,0) -> tier - 1 | O6: =_xlfn.XLOOKUP($A6,'Cleaned - Hospitalisation Detai'!$A$2:$A$2344,'Cleaned - Hospitalisation Detai'!$H$2:$H$2344,0) -> tier - 2 | P6: =_xlfn.XLOOKUP($A6,'Cleaned - Hospitalisation Detai'!$A$2:$A$2344,'Cleaned - Hospitalisation Detai'!$I$2:$I$2344,0) -> R1012 | Q6: =_xlfn.XLOOKUP($A6,'Cleaned - Hospitalisation Detai'!$A$2:$A$2344,'Cleaned - Hospitalisation Detai'!$K$2:$K$2344,0) -> 33
A7: Id6 | B7: =_xlfn.XLOOKUP(A7,'Cleaned - Customer Names '!$A$2:$A$2336,'Cleaned - Customer Names '!$C$2:$C$2336,0) -> Russell B. | C7: =_xlfn.XLOOKUP($A7,'Cleaned - Medical Examinations'!$A$2:$A$2336,'Cleaned - Medical Examinations'!$B$2:$B$2336,0) -> 32.8 | D7: =_xlfn.XLOOKUP($A7,'Cleaned - Medical Examinations'!$A$2:$A$2336,'Cleaned - Medical Examinations'!$C$2:$C$2336,0) -> 6.59 | E7: =_xlfn.XLOOKUP($A7,'Cleaned - Medical Examinations'!$A$2:$A$2336,'Cleaned - Medical Examinations'!$D$2:$D$2336,0) -> No | F7: =_xlfn.XLOOKUP($A7,'Cleaned - Medical Examinations'!$A$2:$A$2336,'Cleaned - Medical Examinations'!$E$2:$E$2336,0) -> No | G7: =_xlfn.XLOOKUP($A7,'Cleaned - Medical Examinations'!$A$2:$A$2336,'Cleaned - Medical Examinations'!$F$2:$F$2336,0) -> No | H7: =_xlfn.XLOOKUP($A7,'Cleaned - Medical Examinations'!$A$2:$A$2336,'Cleaned - Medical Examinations'!$G$2:$G$2336,0) -> 0 | I7: =_xlfn.XLOOKUP($A7,'Cleaned - Medical Examinations'!$A$2:$A$2336,'Cleaned - Medical Examinations'!$H$2:$H$2336,0) -> Yes | J7: =_xlfn.XLOOKUP($A7,'Cleaned - Medical Examinations'!$A$2:$A$2336,'Cleaned - Medical Examinations'!$I$2:$I$2336,0) -> Obesity | K7: =IF(D7>=6.5,"Diabetic","Non-Diabetic") -> Diabetic | L7: =_xlfn.XLOOKUP($A7,'Cleaned - Hospitalisation Detai'!$A$2:$A$2344,'Cleaned - Hospitalisation Detai'!$J$2:$J$2344,0) -> 22862 | M7: =_xlfn.XLOOKUP($A7,'Cleaned - Hospitalisation Detai'!$A$2:$A$2344,'Cleaned - Hospitalisation Detai'!$F$2:$F$2344,0) -> 52590.83 | N7: =_xlfn.XLOOKUP($A7,'Cleaned - Hospitalisation Detai'!$A$2:$A$2344,'Cleaned - Hospitalisation Detai'!$G$2:$G$2344,0) -> tier - 1 | O7: =_xlfn.XLOOKUP($A7,'Cleaned - Hospitalisation Detai'!$A$2:$A$2344,'Cleaned - Hospitalisation Detai'!$H$2:$H$2344,0) -> tier - 3 | P7: =_xlfn.XLOOKUP($A7,'Cleaned - Hospitalisation Detai'!$A$2:$A$2344,'Cleaned - Hospitalisation Detai'!$I$2:$I$2344,0) -> R1011 | Q7: =_xlfn.XLOOKUP($A7,'Cleaned - Hospitalisation Detai'!$A$2:$A$2344,'Cleaned - Hospitalisation Detai'!$K$2:$K$2344,0) -> 60
A8: Id7 | B8: =_xlfn.XLOOKUP(A8,'Cleaned - Customer Names '!$A$2:$A$2336,'Cleaned - Customer Names '!$C$2:$C$2336,0) -> Scott | C8: =_xlfn.XLOOKUP($A8,'Cleaned - Medical Examinations'!$A$2:$A$2336,'Cleaned - Medical Examinations'!$B$2:$B$2336,0) -> 36.4 | D8: =_xlfn.XLOOKUP($A8,'Cleaned - Medical Examinations'!$A$2:$A$2336,'Cleaned - Medical Examinations'!$C$2:$C$2336,0) -> 6.07 | E8: =_xlfn.XLOOKUP($A8,'Cleaned - Medical Examinations'!$A$2:$A$2336,'Cleaned - Medical Examinations'!$D$2:$D$2336,0) -> No | F8: =_xlfn.XLOOKUP($A8,'Cleaned - Medical Examinations'!$A$2:$A$2336,'Cleaned - Medical Examinations'!$E$2:$E$2336,0) -> No | G8: =_xlfn.XLOOKUP($A8,'Cleaned - Medical Examinations'!$A$2:$A$2336,'Cleaned - Medical Examinations'!$F$2:$F$2336,0) -> No | H8: =_xlfn.XLOOKUP($A8,'Cleaned - Medical Examinations'!$A$2:$A$2336,'Cleaned - Medical Examinations'!$G$2:$G$2336,0) -> 0 | I8: =_xlfn.XLOOKUP($A8,'Cleaned - Medical Examinations'!$A$2:$A$2336,'Cleaned - Medical Examinations'!$H$2:$H$2336,0) -> Yes | J8: =_xlfn.XLOOKUP($A8,'Cleaned - Medical Examinations'!$A$2:$A$2336,'Cleaned - Medical Examinations'!$I$2:$I$2336,0) -> Obesity | K8: =IF(D8>=6.5,"Diabetic","Non-Diabetic") -> Non-Diabetic | L8: =_xlfn.XLOOKUP($A8,'Cleaned - Hospitalisation Detai'!$A$2:$A$2344,'Cleaned - Hospitalisation Detai'!$J$2:$J$2344,0) -> 34634 | M8: =_xlfn.XLOOKUP($A8,'Cleaned - Hospitalisation Detai'!$A$2:$A$2344,'Cleaned - Hospitalisation Detai'!$F$2:$F$2344,0) -> 51194.56 | N8: =_xlfn.XLOOKUP($A8,'Cleaned - Hospitalisation Detai'!$A$2:$A$2344,'Cleaned - Hospitalisation Detai'!$G$2:$G$2344,0) -> tier - 1 | O8: =_xlfn.XLOOKUP($A8,'Cleaned - Hospitalisation Detai'!$A$2:$A$2344,'Cleaned - Hospitalisation Detai'!$H$2:$H$2344,0) -> tier - 3 | P8: =_xlfn.XLOOKUP($A8,'Cleaned - Hospitalisation Detai'!$A$2:$A$2344,'Cleaned - Hospitalisation Detai'!$I$2:$I$2344,0) -> R1011 | Q8: =_xlfn.XLOOKUP($A8,'Cleaned - Hospitalisation Detai'!$A$2:$A$2344,'Cleaned - Hospitalisation Detai'!$K$2:$K$2344,0) -> 28
A9: Id8 | B9: =_xlfn.XLOOKUP(A9,'Cleaned - Customer Names '!$A$2:$A$2336,'Cleaned - Customer Names '!$C$2:$C$2336,0) -> Stephen | C9: =_xlfn.XLOOKUP($A9,'Cleaned - Medical Examinations'!$A$2:$A$2336,'Cleaned - Medical Examinations'!$B$2:$B$2336,0) -> 36.96 | D9: =_xlfn.XLOOKUP($A9,'Cleaned - Medical Examinations'!$A$2:$A$2336,'Cleaned - Medical Examinations'!$C$2:$C$2336,0) -> 7.93 | E9: =_xlfn.XLOOKUP($A9,'Cleaned - Medical Examinations'!$A$2:$A$2336,'Cleaned - Medical Examinations'!$D$2:$D$2336,0) -> No | F9: =_xlfn.XLOOKUP($A9,'Cleaned - Medical Examinations'!$A$2:$A$2336,'Cleaned - Medical Examinations'!$E$2:$E$2336,0) -> No | G9: =_xlfn.XLOOKUP($A9,'Cleaned - Medical Examinations'!$A$2:$A$2336,'Cleaned - Medical Examinations'!$F$2:$F$2336,0) -> No | H9: =_xlfn.XLOOKUP($A9,'Cleaned - Medical Examinations'!$A$2:$A$2336,'Cleaned - Medical Examinations'!$G$2:$G$2336,0) -> 3 | I9: =_xlfn.XLOOKUP($A9,'Cleaned - Medical Examinations'!$A$2:$A$2336,'Cleaned - Medical Examinations'!$H$2:$H$2336,0) -> Yes | J9: =_xlfn.XLOOKUP($A9,'Cleaned - Medical Examinations'!$A$2:$A$2336,'Cleaned - Medical Examinations'!$I$2:$I$2336,0) -> Obesity | K9: =IF(D9>=6.5,"Diabetic","Non-Diabetic") -> Diabetic | L9: =_xlfn.XLOOKUP($A9,'Cleaned - Hospitalisation Detai'!$A$2:$A$2344,'Cleaned - Hospitalisation Detai'!$J$2:$J$2344,0) -> 21363 | M9: =_xlfn.XLOOKUP($A9,'Cleaned - Hospitalisation Detai'!$A$2:$A$2344,'Cleaned - Hospitalisation Detai'!$F$2:$F$2344,0) -> 49577.66 | N9: =_xlfn.XLOOKUP($A9,'Cleaned - Hospitalisation Detai'!$A$2:$A$2344,'Cleaned - Hospitalisation Detai'!$G$2:$G$2344,0) -> tier - 2 | O9: =_xlfn.XLOOKUP($A9,'Cleaned - Hospitalisation Detai'!$A$2:$A$2344,'Cleaned - Hospitalisation Detai'!$H$2:$H$2344,0) -> tier - 2 | P9: =_xlfn.XLOOKUP($A9,'Cleaned - Hospitalisation Detai'!$A$2:$A$2344,'Cleaned - Hospitalisation Detai'!$I$2:$I$2344,0) -> R1013 | Q9: =_xlfn.XLOOKUP($A9,'Cleaned - Hospitalisation Detai'!$A$2:$A$2344,'Cleaned - Hospitalisation Detai'!$K$2:$K$2344,0) -> 64
A10: Id9 | B10: =_xlfn.XLOOKUP(A10,'Cleaned - Customer Names '!$A$2:$A$2336,'Cleaned - Customer Names '!$C$2:$C$2336,0) -> Patrick R. | C10: =_xlfn.XLOOKUP($A10,'Cleaned - Medical Examinations'!$A$2:$A$2336,'Cleaned - Medical Examinations'!$B$2:$B$2336,0) -> 41.14 | D10: =_xlfn.XLOOKUP($A10,'Cleaned - Medical Examinations'!$A$2:$A$2336,'Cleaned - Medical Examinations'!$C$2:$C$2336,0) -> 9.58 | E10: =_xlfn.XLOOKUP($A10,'Cleaned - Medical Examinations'!$A$2:$A$2336,'Cleaned - Medical Examinations'!$D$2:$D$2336,0) -> Yes | F10: =_xlfn.XLOOKUP($A10,'Cleaned - Medical Examinations'!$A$2:$A$2336,'Cleaned - Medical Examinations'!$E$2:$E$2336,0) -> No | G10: =_xlfn.XLOOKUP($A10,'Cleaned - Medical Examinations'!$A$2:$A$2336,'Cleaned - Medical Examinations'!$F$2:$F$2336,0) -> Yes | H10: =_xlfn.XLOOKUP($A10,'Cleaned - Medical Examinations'!$A$2:$A$2336,'Cleaned - Medical Examinations'!$G$2:$G$2336,0) -> 1 | I10: =_xlfn.XLOOKUP($A10,'Cleaned - Medical Examinations'!$A$2:$A$2336,'Cleaned - Medical Examinations'!$H$2:$H$2336,0) -> Yes | J10: =_xlfn.XLOOKUP($A10,'Cleaned - Medical Examinations'!$A$2:$A$2336,'Cleaned - Medical Examinations'!$I$2:$I$2336,0) -> Obesity | K10: =IF(D10>=6.5,"Diabetic","Non-Diabetic") -> Diabetic | L10: =_xlfn.XLOOKUP($A10,'Cleaned - Hospitalisation Detai'!$A$2:$A$2344,'Cleaned - Hospitalisation Detai'!$J$2:$J$2344,0) -> 23258 | M10: =_xlfn.XLOOKUP($A10,'Cleaned - Hospitalisation Detai'!$A$2:$A$2344,'Cleaned - Hospitalisation Detai'!$F$2:$F$2344,0) -> 48970.25 | N10: =_xlfn.XLOOKUP($A10,'Cleaned - Hospitalisation Detai'!$A$2:$A$2344,'Cleaned - Hospitalisation Detai'!$G$2:$G$2344,0) -> tier - 1 | O10: =_xlfn.XLOOKUP($A10,'Cleaned - Hospitalisation Detai'!$A$2:$A$2344,'Cleaned - Hospitalisation Detai'!$H$2:$H$2344,0) -> tier - 2 | P10: =_xlfn.XLOOKUP($A10,'Cleaned - Hospitalisation Detai'!$A$2:$A$2344,'Cleaned - Hospitalisation Detai'!$I$2:$I$2344,0) -> R1013 | Q10: =_xlfn.XLOOKUP($A10,'Cleaned - Hospitalisation Detai'!$A$2:$A$2344,'Cleaned - Hospitalisation Detai'!$K$2:$K$2344,0) -> 59
A11: Id10 | B11: =_xlfn.XLOOKUP(A11,'Cleaned - Customer Names '!$A$2:$A$2336,'Cleaned - Customer Names '!$C$2:$C$2336,0) -> Brooke N. | C11: =_xlfn.XLOOKUP($A11,'Cleaned - Medical Examinations'!$A$2:$A$2336,'Cleaned - Medical Examinations'!$B$2:$B$2336,0) -> 38.06 | D11: =_xlfn.XLOOKUP($A11,'Cleaned - Medical Examinations'!$A$2:$A$2336,'Cleaned - Medical Examinations'!$C$2:$C$2336,0) -> 10.79 | E11: =_xlfn.XLOOKUP($A11,'Cleaned - Medical Examinations'!$A$2:$A$2336,'Cleaned - Medical Examinations'!$D$2:$D$2336,0) -> No | F11: =_xlfn.XLOOKUP($A11,'Cleaned - Medical Examinations'!$A$2:$A$2336,'Cleaned - Medical Examinations'!$E$2:$E$2336,0) -> No | G11: =_xlfn.XLOOKUP($A11,'Cleaned - Medical Examinations'!$A$2:$A$2336,'Cleaned - Medical Examinations'!$F$2:$F$2336,0) -> No | H11: =_xlfn.XLOOKUP($A11,'Cleaned - Medical Examinations'!$A$2:$A$2336,'Cleaned - Medical Examinations'!$G$2:$G$2336,0) -> 0 | I11: =_xlfn.XLOOKUP($A11,'Cleaned - Medical Examinations'!$A$2:$A$2336,'Cleaned - Medical Examinations'!$H$2:$H$2336,0) -> Yes | J11: =_xlfn.XLOOKUP($A11,'Cleaned - Medical Examinations'!$A$2:$A$2336,'Cleaned - Medical Examinations'!$I$2:$I$2336,0) -> Obesity | K11: =IF(D11>=6.5,"Diabetic","Non-Diabetic") -> Diabetic | L11: =_xlfn.XLOOKUP($A11,'Cleaned - Hospitalisation Detai'!$A$2:$A$2344,'Cleaned - Hospitalisation Detai'!$J$2:$J$2344,0) -> 28853 | M11: =_xlfn.XLOOKUP($A11,'Cleaned - Hospitalisation Detai'!$A$2:$A$2344,'Cleaned - Hospitalisation Detai'!$F$2:$F$2344,0) -> 48885.14 | N11: =_xlfn.XLOOKUP($A11,'Cleaned - Hospitalisation Detai'!$A$2:$A$2344,'Cleaned - Hospitalisation Detai'!$G$2:$G$2344,0) -> tier - 1 | O11: =_xlfn.XLOOKUP($A11,'Cleaned - Hospitalisation Detai'!$A$2:$A$2344,'Cleaned - Hospitalisation Detai'!$H$2:$H$2344,0) -> tier - 2 | P11: =_xlfn.XLOOKUP($A11,'Cleaned - Hospitalisation Detai'!$A$2:$A$2344,'Cleaned - Hospitalisation Detai'!$I$2:$I$2344,0) -> R1013 | Q11: =_xlfn.XLOOKUP($A11,'Cleaned - Hospitalisation Detai'!$A$2:$A$2344,'Cleaned - Hospitalisation Detai'!$K$2:$K$2344,0) -> 44
